<?xml version="1.0" ?>
<!-- =================================================================================== -->
<!-- |    This document was autogenerated by xacro from kobuki_hexagons_kinect.urdf.xacro | -->
<!-- |    EDITING THIS FILE BY HAND IS NOT RECOMMENDED                                 | -->
<!-- =================================================================================== -->
<!--
    - Base      : kobuki
    - Stacks    : hexagons
    - 3d Sensor : kinect
-->
<robot name="turtlebot" xmlns:xacro="http://ros.org/wiki/xacro">
  <!-- General -->
  <!-- 
    These properties must be observed by any machine
    that wants to be defined as a turtlebot. Refer
    to the REP for more details.
    
    http://www.ros.org/reps/rep-0119.html
   -->
  <!--
   ======================================================================
   - REP 119 : Rgb camera link relative to the Base link 
   ====================================================================== 
     Base link is currently defined as the rotational centre on the bottom
     of the base mould. For both create and kobuki this is actually exactly
     the same 3d world point. 
     
     This may cause an issue with a base with much different floor clearance.
     Should we be using base_footprint for this specification instead?
 
     Note: REP needs to be updated with the information below 
     (currently in development and awaiting feedback)
   -->
  <!--	<property name="cam_py" value="-0.0125" /> Y varies for different configurations. get sets in sensors_urdf -->
  <!-- Bases -->
  <!-- Macro for TurtleBot body. Including Gazebo extensions, but does not include Kinect -->
  <!-- Kobuki -->
  <!-- Stacks -->
  <!-- Xacro properties -->
  <!-- Xacro macros -->
  <!-- Pole macros -->
  <!-- 
    Stack macro - all the components relative transforms are made with respect 
    to the parent link (usually base_link). They could be made relative to each
    other, but there is no necessary reason to do so.
  -->
  <!-- 3D Sensors -->
  <!-- Microsoft Kinect / ASUS Xtion PRO Live for simulation -->
  <!-- 
    These properties must be observed by any machine
    that wants to be defined as a turtlebot. Refer
    to the REP for more details.
    
    http://www.ros.org/reps/rep-0119.html
   -->
  <!--
   ======================================================================
   - REP 119 : Rgb camera link relative to the Base link 
   ====================================================================== 
     Base link is currently defined as the rotational centre on the bottom
     of the base mould. For both create and kobuki this is actually exactly
     the same 3d world point. 
     
     This may cause an issue with a base with much different floor clearance.
     Should we be using base_footprint for this specification instead?
 
     Note: REP needs to be updated with the information below 
     (currently in development and awaiting feedback)
   -->
  <!--	<property name="cam_py" value="-0.0125" /> Y varies for different configurations. get sets in sensors_urdf -->
  <!-- Parameterised in part by the values in turtlebot_properties.urdf.xacro -->
  <!-- Microsoft Kinect / ASUS Xtion PRO Live for simulation -->
  <!-- 
    These properties must be observed by any machine
    that wants to be defined as a turtlebot. Refer
    to the REP for more details.
    
    http://www.ros.org/reps/rep-0119.html
   -->
  <!--
   ======================================================================
   - REP 119 : Rgb camera link relative to the Base link 
   ====================================================================== 
     Base link is currently defined as the rotational centre on the bottom
     of the base mould. For both create and kobuki this is actually exactly
     the same 3d world point. 
     
     This may cause an issue with a base with much different floor clearance.
     Should we be using base_footprint for this specification instead?
 
     Note: REP needs to be updated with the information below 
     (currently in development and awaiting feedback)
   -->
  <!--	<property name="cam_py" value="-0.0125" /> Y varies for different configurations. get sets in sensors_urdf -->
  <!-- Xacro properties -->
  <!-- Parameterised in part by the values in turtlebot_properties.urdf.xacro -->
  <!-- Microsoft Kinect / ASUS Xtion PRO Live for simulation -->
  <!-- 
    These properties must be observed by any machine
    that wants to be defined as a turtlebot. Refer
    to the REP for more details.
    
    http://www.ros.org/reps/rep-0119.html
   -->
  <!--
   ======================================================================
   - REP 119 : Rgb camera link relative to the Base link 
   ====================================================================== 
     Base link is currently defined as the rotational centre on the bottom
     of the base mould. For both create and kobuki this is actually exactly
     the same 3d world point. 
     
     This may cause an issue with a base with much different floor clearance.
     Should we be using base_footprint for this specification instead?
 
     Note: REP needs to be updated with the information below 
     (currently in development and awaiting feedback)
   -->
  <!--	<property name="cam_py" value="-0.0125" /> Y varies for different configurations. get sets in sensors_urdf -->
  <!-- Xacro properties -->
  <!-- Parameterised in part by the values in turtlebot_properties.urdf.xacro -->
  <!--Since we do not want to edit the turtlebot description we add the arm and elevator information here -->
  <material name="white">
    <color rgba="0.87 0.90 0.87 1.0"/>
  </material>
  <material name="black">
    <color rgba="0.0 0.0 0.0 1.0"/>
  </material>
  <material name="green">
    <color rgba="0.22 0.32 0.14 1.0"/>
  </material>
  <link name="base_footprint"/>
  <!--
       Base link is set at the bottom of the base mould.
       This is done to be compatible with the way base link
       was configured for turtlebot 1. Refer to
       
       https://github.com/turtlebot/turtlebot/issues/40
       
       To put the base link at the more oft used wheel
       axis, set the z-distance from the base_footprint
       to 0.352.
      -->
  <joint name="base_joint" type="fixed">
    <origin rpy="0 0 0" xyz="0 0 0.0102"/>
    <parent link="base_footprint"/>
    <child link="base_link"/>
  </joint>
  <link name="base_link">
    <visual>
      <geometry>
        <!-- new mesh -->
        <mesh filename="package://kobuki_description/meshes/main_body.dae"/>
      </geometry>
      <origin rpy="0 0 0" xyz="0.001 0 0.05199"/>
    </visual>
    <collision>
      <geometry>
        <cylinder length="0.10938" radius="0.178"/>
      </geometry>
      <origin rpy="0 0 0" xyz="0.0 0 0.05949"/>
    </collision>
    <inertial>
      <!-- COM experimentally determined -->
      <origin xyz="0.01 0 0"/>
      <mass value="2.4"/>
      <!-- 2.4/2.6 kg for small/big battery pack -->
      <!-- Kobuki's inertia tensor is approximated by a cylinder with homogeneous mass distribution
             More details: http://en.wikipedia.org/wiki/List_of_moment_of_inertia_tensors
             m = 2.4 kg; h = 0.09 m; r = 0.175 m
             ixx = 1/12 * m * (3 * r^2 + h^2)
             iyy = 1/12 * m * (3 * r^2 + h^2)
             izz = 1/2 * m * r^2 
          -->
      <inertia ixx="0.019995" ixy="0.0" ixz="0.0" iyy="0.019995" iyz="0.0" izz="0.03675"/>
    </inertial>
  </link>
  <joint name="wheel_left_joint" type="continuous">
    <parent link="base_link"/>
    <child link="wheel_left_link"/>
    <origin rpy="-1.5706 0 0" xyz="0.00 0.115 0.0250"/>
    <axis xyz="0 0 1"/>
  </joint>
  <link name="wheel_left_link">
    <visual>
      <geometry>
        <mesh filename="package://kobuki_description/meshes/wheel.dae"/>
      </geometry>
      <origin rpy="0 0 0" xyz="0 0 0"/>
    </visual>
    <collision>
      <geometry>
        <cylinder length="0.0206" radius="0.0352"/>
      </geometry>
      <origin rpy="0 0 0" xyz="0 0 0"/>
    </collision>
    <inertial>
      <mass value="0.01"/>
      <origin xyz="0 0 0"/>
      <inertia ixx="0.001" ixy="0.0" ixz="0.0" iyy="0.001" iyz="0.0" izz="0.001"/>
    </inertial>
  </link>
  <joint name="wheel_right_joint" type="continuous">
    <parent link="base_link"/>
    <child link="wheel_right_link"/>
    <origin rpy="-1.5706 0 0" xyz="0.00 -0.115 0.0250"/>
    <axis xyz="0 0 1"/>
  </joint>
  <link name="wheel_right_link">
    <visual>
      <geometry>
        <mesh filename="package://kobuki_description/meshes/wheel.dae"/>
      </geometry>
      <origin rpy="0 0 0" xyz="0 0 0"/>
    </visual>
    <collision>
      <geometry>
        <cylinder length="0.0206" radius="0.0350"/>
      </geometry>
      <origin rpy="0 0 0" xyz="0 0 0"/>
    </collision>
    <inertial>
      <mass value="0.01"/>
      <origin xyz="0 0 0"/>
      <inertia ixx="0.001" ixy="0.0" ixz="0.0" iyy="0.001" iyz="0.0" izz="0.001"/>
    </inertial>
  </link>
  <joint name="caster_front_joint" type="fixed">
    <parent link="base_link"/>
    <child link="caster_front_link"/>
    <origin rpy="-1.5706 0 0" xyz="0.115 0.0 0.007"/>
  </joint>
  <link name="caster_front_link">
    <collision>
      <geometry>
        <cylinder length="0.0176" radius="0.017"/>
      </geometry>
      <origin rpy="0 0 0" xyz="0 0 0"/>
    </collision>
    <inertial>
      <mass value="0.01"/>
      <origin xyz="0 0 0"/>
      <inertia ixx="0.001" ixy="0.0" ixz="0.0" iyy="0.001" iyz="0.0" izz="0.001"/>
    </inertial>
  </link>
  <joint name="caster_back_joint" type="fixed">
    <parent link="base_link"/>
    <child link="caster_back_link"/>
    <origin rpy="-1.5706 0 0" xyz="-0.135 0.0 0.009"/>
  </joint>
  <link name="caster_back_link">
    <collision>
      <geometry>
        <cylinder length="0.0176" radius="0.017"/>
      </geometry>
      <origin rpy="0 0 0" xyz="0 0 0"/>
    </collision>
    <inertial>
      <mass value="0.01"/>
      <origin xyz="0 0 0"/>
      <inertia ixx="0.001" ixy="0.0" ixz="0.0" iyy="0.001" iyz="0.0" izz="0.001"/>
    </inertial>
  </link>
  <!-- Kobuki's sensors -->
  <joint name="gyro_joint" type="fixed">
    <axis xyz="0 1 0"/>
    <origin rpy="0 0 0" xyz="0.056 0.062 0.0202"/>
    <parent link="base_link"/>
    <child link="gyro_link"/>
  </joint>
  <link name="gyro_link">
    <inertial>
      <mass value="0.001"/>
      <origin rpy="0 0 0" xyz="0 0 0"/>
      <inertia ixx="0.0001" ixy="0" ixz="0" iyy="0.000001" iyz="0" izz="0.0001"/>
    </inertial>
  </link>
  <joint name="cliff_sensor_left_joint" type="fixed">
    <origin rpy="0 1.5706 0" xyz="0.08734 0.13601 0.0214"/>
    <parent link="base_link"/>
    <child link="cliff_sensor_left_link"/>
  </joint>
  <link name="cliff_sensor_left_link">
    <inertial>
      <mass value="0.0001"/>
      <origin xyz="0 0 0"/>
      <inertia ixx="0.0001" ixy="0.0" ixz="0.0" iyy="0.0001" iyz="0.0" izz="0.0001"/>
    </inertial>
  </link>
  <joint name="cliff_sensor_right_joint" type="fixed">
    <origin rpy="0 1.5706 0" xyz="0.085 -0.13601 0.0214"/>
    <parent link="base_link"/>
    <child link="cliff_sensor_right_link"/>
  </joint>
  <link name="cliff_sensor_right_link">
    <inertial>
      <mass value="0.0001"/>
      <origin xyz="0 0 0"/>
      <inertia ixx="0.0001" ixy="0.0" ixz="0.0" iyy="0.0001" iyz="0.0" izz="0.0001"/>
    </inertial>
  </link>
  <joint name="cliff_sensor_front_joint" type="fixed">
    <origin rpy="0 1.5706 0" xyz="0.156 0.00 0.0214"/>
    <parent link="base_link"/>
    <child link="cliff_sensor_front_link"/>
  </joint>
  <link name="cliff_sensor_front_link">
    <inertial>
      <mass value="0.0001"/>
      <origin xyz="0 0 0"/>
      <inertia ixx="0.0001" ixy="0.0" ixz="0.0" iyy="0.0001" iyz="0.0" izz="0.0001"/>
    </inertial>
  </link>
  <!-- Kobuki Gazebo simulation details -->
  <gazebo reference="wheel_left_link">
    <mu1>1.0</mu1>
    <mu2>1.0</mu2>
    <kp>1000000.0</kp>
    <kd>100.0</kd>
    <minDepth>0.001</minDepth>
    <maxVel>1.0</maxVel>
  </gazebo>
  <gazebo reference="wheel_right_link">
    <mu1>1.0</mu1>
    <mu2>1.0</mu2>
    <kp>1000000.0</kp>
    <kd>100.0</kd>
    <minDepth>0.001</minDepth>
    <maxVel>1.0</maxVel>
  </gazebo>
  <gazebo reference="caster_front_link">
    <mu1>0.0</mu1>
    <mu2>0.0</mu2>
    <kp>1000000.0</kp>
    <kd>100.0</kd>
    <minDepth>0.001</minDepth>
    <maxVel>1.0</maxVel>
  </gazebo>
  <gazebo reference="caster_back_link">
    <mu1>0.0</mu1>
    <mu2>0.0</mu2>
    <kp>1000000.0</kp>
    <kd>100.0</kd>
    <minDepth>0.001</minDepth>
    <maxVel>1.0</maxVel>
  </gazebo>
  <gazebo reference="base_link">
    <mu1>0.3</mu1>
    <mu2>0.3</mu2>
    <sensor name="bumpers" type="contact">
      <always_on>1</always_on>
      <update_rate>50.0</update_rate>
      <visualize>true</visualize>
      <contact>
        <collision>base_footprint_collision_base_link</collision>
      </contact>
    </sensor>
  </gazebo>
  <gazebo reference="cliff_sensor_left_link">
    <sensor name="cliff_sensor_left" type="ray">
      <always_on>true</always_on>
      <update_rate>50</update_rate>
      <visualize>true</visualize>
      <ray>
        <scan>
          <horizontal>
            <samples>50</samples>
            <resolution>1.0</resolution>
            <min_angle>-0.0436</min_angle>
            <!-- -2.5 degree -->
            <max_angle>0.0436</max_angle>
            <!-- 2.5 degree -->
          </horizontal>
          <!--            Can't use vertical rays until this bug is resolved: -->
          <!--            https://bitbucket.org/osrf/gazebo/issue/509/vertical-sensor-doesnt-works -->
          <!-- 	          <vertical> -->
          <!-- 	            <samples>50</samples> -->
          <!-- 	            <resolution>1.0</resolution> -->
          <!-- 	            <min_angle>-0.0436</min_angle>  -2.5 degree -->
          <!-- 	            <max_angle>0.0436</max_angle> 2.5 degree -->
          <!-- 	          </vertical> -->
        </scan>
        <range>
          <min>0.01</min>
          <max>0.15</max>
          <resolution>1.0</resolution>
        </range>
      </ray>
    </sensor>
  </gazebo>
  <gazebo reference="cliff_sensor_right_link">
    <sensor name="cliff_sensor_right" type="ray">
      <always_on>true</always_on>
      <update_rate>50</update_rate>
      <visualize>true</visualize>
      <ray>
        <scan>
          <horizontal>
            <samples>50</samples>
            <resolution>1.0</resolution>
            <min_angle>-0.0436</min_angle>
            <!-- -2.5 degree -->
            <max_angle>0.0436</max_angle>
            <!-- 2.5 degree -->
          </horizontal>
          <!--            Can't use vertical rays until this bug is resolved: -->
          <!--            https://bitbucket.org/osrf/gazebo/issue/509/vertical-sensor-doesnt-works -->
          <!-- 	          <vertical> -->
          <!-- 	            <samples>50</samples> -->
          <!-- 	            <resolution>1.0</resolution> -->
          <!-- 	            <min_angle>-0.0436</min_angle>  -2.5 degree -->
          <!-- 	            <max_angle>0.0436</max_angle> 2.5 degree -->
          <!-- 	          </vertical> -->
        </scan>
        <range>
          <min>0.01</min>
          <max>0.15</max>
          <resolution>1.0</resolution>
        </range>
      </ray>
    </sensor>
  </gazebo>
  <gazebo reference="cliff_sensor_front_link">
    <sensor name="cliff_sensor_front" type="ray">
      <always_on>true</always_on>
      <update_rate>50</update_rate>
      <visualize>true</visualize>
      <ray>
        <scan>
          <horizontal>
            <samples>50</samples>
            <resolution>1.0</resolution>
            <min_angle>-0.0436</min_angle>
            <!-- -2.5 degree -->
            <max_angle>0.0436</max_angle>
            <!-- 2.5 degree -->
          </horizontal>
          <!-- 	          Can't use vertical rays until this bug is resolved: -->
          <!--            https://bitbucket.org/osrf/gazebo/issue/509/vertical-sensor-doesnt-works -->
          <!-- 	          <vertical> -->
          <!-- 	            <samples>50</samples> -->
          <!-- 	            <resolution>1.0</resolution> -->
          <!-- 	            <min_angle>-0.0436</min_angle>  -2.5 degree -->
          <!-- 	            <max_angle>0.0436</max_angle> 2.5 degree -->
          <!-- 	          </vertical> -->
        </scan>
        <range>
          <min>0.01</min>
          <max>0.15</max>
          <resolution>1.0</resolution>
        </range>
      </ray>
    </sensor>
  </gazebo>
  <gazebo reference="gyro_link">
    <sensor name="imu" type="imu">
      <always_on>true</always_on>
      <update_rate>50</update_rate>
      <visualize>false</visualize>
      <imu>
        <noise>
          <type>gaussian</type>
          <rate>
            <mean>0.0</mean>
            <stddev>1.96e-06</stddev>
            <!-- 0.25 x 0.25 (deg/s) -->
            <bias_mean>0.0</bias_mean>
            <bias_stddev>0.0</bias_stddev>
          </rate>
          <accel>
            <!-- not used in the plugin and real robot, hence using tutorial values -->
            <mean>0.0</mean>
            <stddev>1.7e-2</stddev>
            <bias_mean>0.1</bias_mean>
            <bias_stddev>0.001</bias_stddev>
          </accel>
        </noise>
      </imu>
    </sensor>
  </gazebo>
  <gazebo>
    <plugin filename="libgazebo_ros_kobuki.so" name="kobuki_controller">
      <publish_tf>1</publish_tf>
      <left_wheel_joint_name>wheel_left_joint</left_wheel_joint_name>
      <right_wheel_joint_name>wheel_right_joint</right_wheel_joint_name>
      <wheel_separation>.230</wheel_separation>
      <wheel_diameter>0.070</wheel_diameter>
      <torque>1.0</torque>
      <velocity_command_timeout>0.6</velocity_command_timeout>
      <cliff_sensor_left_name>cliff_sensor_left</cliff_sensor_left_name>
      <cliff_sensor_center_name>cliff_sensor_front</cliff_sensor_center_name>
      <cliff_sensor_right_name>cliff_sensor_right</cliff_sensor_right_name>
      <cliff_detection_threshold>0.04</cliff_detection_threshold>
      <bumper_name>bumpers</bumper_name>
      <imu_name>imu</imu_name>
    </plugin>
  </gazebo>
  <joint name="pole_bottom_0_joint" type="fixed">
    <origin rpy="0 0 0" xyz="0.12 0.082 0.1028"/>
    <parent link="base_link"/>
    <child link="pole_bottom_0_link"/>
  </joint>
  <link name="pole_bottom_0_link">
    <visual>
      <origin rpy="0 0 0" xyz="0 0 0"/>
      <geometry>
        <mesh filename="package://turtlebot_description/meshes/stacks/hexagons/pole_bottom.dae"/>
      </geometry>
    </visual>
    <collision>
      <origin rpy="0 0 0" xyz="0 0 0"/>
      <geometry>
        <cylinder length="0.0492" radius="0.006"/>
      </geometry>
    </collision>
    <inertial>
      <mass value="0.008"/>
      <origin rpy="0 0 0" xyz="0 0 0"/>
      <inertia ixx="0.000001686" ixy="0.0" ixz="0.0" iyy="0.000001686" iyz="0.0" izz="0.000000144"/>
    </inertial>
  </link>
  <joint name="pole_bottom_1_joint" type="fixed">
    <origin rpy="0 0 0" xyz="0.055 0.12 0.1028"/>
    <parent link="base_link"/>
    <child link="pole_bottom_1_link"/>
  </joint>
  <link name="pole_bottom_1_link">
    <visual>
      <origin rpy="0 0 0" xyz="0 0 0"/>
      <geometry>
        <mesh filename="package://turtlebot_description/meshes/stacks/hexagons/pole_bottom.dae"/>
      </geometry>
    </visual>
    <collision>
      <origin rpy="0 0 0" xyz="0 0 0"/>
      <geometry>
        <cylinder length="0.0492" radius="0.006"/>
      </geometry>
    </collision>
    <inertial>
      <mass value="0.008"/>
      <origin rpy="0 0 0" xyz="0 0 0"/>
      <inertia ixx="0.000001686" ixy="0.0" ixz="0.0" iyy="0.000001686" iyz="0.0" izz="0.000000144"/>
    </inertial>
  </link>
  <joint name="pole_bottom_2_joint" type="fixed">
    <origin rpy="0 0 0" xyz="-0.055 0.12 0.1028"/>
    <parent link="base_link"/>
    <child link="pole_bottom_2_link"/>
  </joint>
  <link name="pole_bottom_2_link">
    <visual>
      <origin rpy="0 0 0" xyz="0 0 0"/>
      <geometry>
        <mesh filename="package://turtlebot_description/meshes/stacks/hexagons/pole_bottom.dae"/>
      </geometry>
    </visual>
    <collision>
      <origin rpy="0 0 0" xyz="0 0 0"/>
      <geometry>
        <cylinder length="0.0492" radius="0.006"/>
      </geometry>
    </collision>
    <inertial>
      <mass value="0.008"/>
      <origin rpy="0 0 0" xyz="0 0 0"/>
      <inertia ixx="0.000001686" ixy="0.0" ixz="0.0" iyy="0.000001686" iyz="0.0" izz="0.000000144"/>
    </inertial>
  </link>
  <joint name="pole_bottom_3_joint" type="fixed">
    <origin rpy="0 0 0" xyz="0.12 -0.082 0.1028"/>
    <parent link="base_link"/>
    <child link="pole_bottom_3_link"/>
  </joint>
  <link name="pole_bottom_3_link">
    <visual>
      <origin rpy="0 0 0" xyz="0 0 0"/>
      <geometry>
        <mesh filename="package://turtlebot_description/meshes/stacks/hexagons/pole_bottom.dae"/>
      </geometry>
    </visual>
    <collision>
      <origin rpy="0 0 0" xyz="0 0 0"/>
      <geometry>
        <cylinder length="0.0492" radius="0.006"/>
      </geometry>
    </collision>
    <inertial>
      <mass value="0.008"/>
      <origin rpy="0 0 0" xyz="0 0 0"/>
      <inertia ixx="0.000001686" ixy="0.0" ixz="0.0" iyy="0.000001686" iyz="0.0" izz="0.000000144"/>
    </inertial>
  </link>
  <joint name="pole_bottom_4_joint" type="fixed">
    <origin rpy="0 0 0" xyz="0.055 -0.12 0.1028"/>
    <parent link="base_link"/>
    <child link="pole_bottom_4_link"/>
  </joint>
  <link name="pole_bottom_4_link">
    <visual>
      <origin rpy="0 0 0" xyz="0 0 0"/>
      <geometry>
        <mesh filename="package://turtlebot_description/meshes/stacks/hexagons/pole_bottom.dae"/>
      </geometry>
    </visual>
    <collision>
      <origin rpy="0 0 0" xyz="0 0 0"/>
      <geometry>
        <cylinder length="0.0492" radius="0.006"/>
      </geometry>
    </collision>
    <inertial>
      <mass value="0.008"/>
      <origin rpy="0 0 0" xyz="0 0 0"/>
      <inertia ixx="0.000001686" ixy="0.0" ixz="0.0" iyy="0.000001686" iyz="0.0" izz="0.000000144"/>
    </inertial>
  </link>
  <joint name="pole_bottom_5_joint" type="fixed">
    <origin rpy="0 0 0" xyz="-0.055 -0.12 0.1028"/>
    <parent link="base_link"/>
    <child link="pole_bottom_5_link"/>
  </joint>
  <link name="pole_bottom_5_link">
    <visual>
      <origin rpy="0 0 0" xyz="0 0 0"/>
      <geometry>
        <mesh filename="package://turtlebot_description/meshes/stacks/hexagons/pole_bottom.dae"/>
      </geometry>
    </visual>
    <collision>
      <origin rpy="0 0 0" xyz="0 0 0"/>
      <geometry>
        <cylinder length="0.0492" radius="0.006"/>
      </geometry>
    </collision>
    <inertial>
      <mass value="0.008"/>
      <origin rpy="0 0 0" xyz="0 0 0"/>
      <inertia ixx="0.000001686" ixy="0.0" ixz="0.0" iyy="0.000001686" iyz="0.0" izz="0.000000144"/>
    </inertial>
  </link>
  <joint name="plate_bottom_joint" type="fixed">
    <origin rpy="0 0 0" xyz="0.02364 0.0 0.1306"/>
    <parent link="base_link"/>
    <child link="plate_bottom_link"/>
  </joint>
  <link name="plate_bottom_link">
    <visual>
      <origin rpy="0 0 0" xyz="0 0 0"/>
      <geometry>
        <mesh filename="package://turtlebot_description/meshes/stacks/hexagons/plate_bottom.dae"/>
      </geometry>
    </visual>
    <collision>
      <origin rpy="0 0 0" xyz="-0.02364 0 0"/>
      <geometry>
        <cylinder length="0.006" radius="0.170"/>
      </geometry>
    </collision>
    <inertial>
      <mass value="0.520"/>
      <origin xyz="0 0 0"/>
      <inertia ixx="0.003328" ixy="0.0" ixz="0.0" iyy="0.003328" iyz="0.0" izz="0.006656"/>
    </inertial>
  </link>
  <joint name="pole_middle_0_joint" type="fixed">
    <origin rpy="0 0 0" xyz="0.0381 0.1505 0.164"/>
    <parent link="base_link"/>
    <child link="pole_middle_0_link"/>
  </joint>
  <link name="pole_middle_0_link">
    <visual>
      <origin rpy="0 3.1412 0" xyz="0 0 0"/>
      <geometry>
        <mesh filename="package://turtlebot_description/meshes/stacks/hexagons/pole_middle.dae"/>
      </geometry>
    </visual>
    <collision>
      <origin rpy="0 0 0" xyz="0 0 0"/>
      <geometry>
        <cylinder length="0.0608" radius="0.006"/>
      </geometry>
    </collision>
    <inertial>
      <mass value="0.012"/>
      <origin xyz="0 0 0"/>
      <inertia ixx="0.000003805" ixy="0.0" ixz="0.0" iyy="0.000003805" iyz="0.0" izz="0.000000216"/>
    </inertial>
  </link>
  <joint name="pole_middle_1_joint" type="fixed">
    <origin rpy="0 0 0" xyz="0.0381 -0.1505 0.164"/>
    <parent link="base_link"/>
    <child link="pole_middle_1_link"/>
  </joint>
  <link name="pole_middle_1_link">
    <visual>
      <origin rpy="0 3.1412 0" xyz="0 0 0"/>
      <geometry>
        <mesh filename="package://turtlebot_description/meshes/stacks/hexagons/pole_middle.dae"/>
      </geometry>
    </visual>
    <collision>
      <origin rpy="0 0 0" xyz="0 0 0"/>
      <geometry>
        <cylinder length="0.0608" radius="0.006"/>
      </geometry>
    </collision>
    <inertial>
      <mass value="0.012"/>
      <origin xyz="0 0 0"/>
      <inertia ixx="0.000003805" ixy="0.0" ixz="0.0" iyy="0.000003805" iyz="0.0" izz="0.000000216"/>
    </inertial>
  </link>
  <joint name="pole_middle_2_joint" type="fixed">
    <origin rpy="0 0 0" xyz="-0.0381 0.1505 0.164"/>
    <parent link="base_link"/>
    <child link="pole_middle_2_link"/>
  </joint>
  <link name="pole_middle_2_link">
    <visual>
      <origin rpy="0 3.1412 0" xyz="0 0 0"/>
      <geometry>
        <mesh filename="package://turtlebot_description/meshes/stacks/hexagons/pole_middle.dae"/>
      </geometry>
    </visual>
    <collision>
      <origin rpy="0 0 0" xyz="0 0 0"/>
      <geometry>
        <cylinder length="0.0608" radius="0.006"/>
      </geometry>
    </collision>
    <inertial>
      <mass value="0.012"/>
      <origin xyz="0 0 0"/>
      <inertia ixx="0.000003805" ixy="0.0" ixz="0.0" iyy="0.000003805" iyz="0.0" izz="0.000000216"/>
    </inertial>
  </link>
  <joint name="pole_middle_3_joint" type="fixed">
    <origin rpy="0 0 0" xyz="-0.0381 -0.1505 0.164"/>
    <parent link="base_link"/>
    <child link="pole_middle_3_link"/>
  </joint>
  <link name="pole_middle_3_link">
    <visual>
      <origin rpy="0 3.1412 0" xyz="0 0 0"/>
      <geometry>
        <mesh filename="package://turtlebot_description/meshes/stacks/hexagons/pole_middle.dae"/>
      </geometry>
    </visual>
    <collision>
      <origin rpy="0 0 0" xyz="0 0 0"/>
      <geometry>
        <cylinder length="0.0608" radius="0.006"/>
      </geometry>
    </collision>
    <inertial>
      <mass value="0.012"/>
      <origin xyz="0 0 0"/>
      <inertia ixx="0.000003805" ixy="0.0" ixz="0.0" iyy="0.000003805" iyz="0.0" izz="0.000000216"/>
    </inertial>
  </link>
  <joint name="plate_middle_joint" type="fixed">
    <origin rpy="0 0 0" xyz="-0.01364 0.0 0.1874"/>
    <parent link="base_link"/>
    <child link="plate_middle_link"/>
  </joint>
  <link name="plate_middle_link">
    <visual>
      <origin rpy="0 0 0" xyz="0 0 0"/>
      <geometry>
        <mesh filename="package://turtlebot_description/meshes/stacks/hexagons/plate_middle.dae"/>
      </geometry>
    </visual>
    <collision>
      <origin rpy="0 0 0" xyz="0.01364 0.0 0.0"/>
      <geometry>
        <cylinder length="0.006" radius="0.170"/>
      </geometry>
    </collision>
    <inertial>
      <mass value="0.520"/>
      <origin xyz="0 0 0"/>
      <inertia ixx="0.003328" ixy="0.0" ixz="0.0" iyy="0.003328" iyz="0.0" izz="0.006656"/>
    </inertial>
  </link>
  <joint name="pole_top_0_joint" type="fixed">
    <origin rpy="0 0 0" xyz="0.0381 0.1505 0.292"/>
    <parent link="base_link"/>
    <child link="pole_top_0_link"/>
  </joint>
  <link name="pole_top_0_link">
    <visual>
      <origin rpy="0 0 0" xyz=" 0 0 0"/>
      <geometry>
        <mesh filename="package://turtlebot_description/meshes/stacks/hexagons/pole_top.dae"/>
      </geometry>
    </visual>
    <collision>
      <origin rpy="0 0 0" xyz="0 0 0"/>
      <geometry>
        <cylinder length="0.2032" radius="0.006"/>
      </geometry>
    </collision>
    <inertial>
      <mass value="0.060"/>
      <origin xyz="0 0 0"/>
      <inertia ixx="0.000206991" ixy="0.0" ixz="0.0" iyy="0.000206991" iyz="0.0" izz="0.000001080"/>
    </inertial>
  </link>
  <joint name="pole_top_1_joint" type="fixed">
    <origin rpy="0 0 0" xyz="0.0381 -0.1505 0.292"/>
    <parent link="base_link"/>
    <child link="pole_top_1_link"/>
  </joint>
  <link name="pole_top_1_link">
    <visual>
      <origin rpy="0 0 0" xyz=" 0 0 0"/>
      <geometry>
        <mesh filename="package://turtlebot_description/meshes/stacks/hexagons/pole_top.dae"/>
      </geometry>
    </visual>
    <collision>
      <origin rpy="0 0 0" xyz="0 0 0"/>
      <geometry>
        <cylinder length="0.2032" radius="0.006"/>
      </geometry>
    </collision>
    <inertial>
      <mass value="0.060"/>
      <origin xyz="0 0 0"/>
      <inertia ixx="0.000206991" ixy="0.0" ixz="0.0" iyy="0.000206991" iyz="0.0" izz="0.000001080"/>
    </inertial>
  </link>
  <joint name="pole_top_2_joint" type="fixed">
    <origin rpy="0 0 0" xyz="-0.0381 0.1505 0.292"/>
    <parent link="base_link"/>
    <child link="pole_top_2_link"/>
  </joint>
  <link name="pole_top_2_link">
    <visual>
      <origin rpy="0 0 0" xyz=" 0 0 0"/>
      <geometry>
        <mesh filename="package://turtlebot_description/meshes/stacks/hexagons/pole_top.dae"/>
      </geometry>
    </visual>
    <collision>
      <origin rpy="0 0 0" xyz="0 0 0"/>
      <geometry>
        <cylinder length="0.2032" radius="0.006"/>
      </geometry>
    </collision>
    <inertial>
      <mass value="0.060"/>
      <origin xyz="0 0 0"/>
      <inertia ixx="0.000206991" ixy="0.0" ixz="0.0" iyy="0.000206991" iyz="0.0" izz="0.000001080"/>
    </inertial>
  </link>
  <joint name="pole_top_3_joint" type="fixed">
    <origin rpy="0 0 0" xyz="-0.0381 -0.1505 0.292"/>
    <parent link="base_link"/>
    <child link="pole_top_3_link"/>
  </joint>
  <link name="pole_top_3_link">
    <visual>
      <origin rpy="0 0 0" xyz=" 0 0 0"/>
      <geometry>
        <mesh filename="package://turtlebot_description/meshes/stacks/hexagons/pole_top.dae"/>
      </geometry>
    </visual>
    <collision>
      <origin rpy="0 0 0" xyz="0 0 0"/>
      <geometry>
        <cylinder length="0.2032" radius="0.006"/>
      </geometry>
    </collision>
    <inertial>
      <mass value="0.060"/>
      <origin xyz="0 0 0"/>
      <inertia ixx="0.000206991" ixy="0.0" ixz="0.0" iyy="0.000206991" iyz="0.0" izz="0.000001080"/>
    </inertial>
  </link>
  <joint name="pole_kinect_0_joint" type="fixed">
    <origin rpy="0 0 0" xyz="-0.1024 0.098 0.2372"/>
    <parent link="base_link"/>
    <child link="pole_kinect_0_link"/>
  </joint>
  <link name="pole_kinect_0_link">
    <visual>
      <origin rpy="0 0 0" xyz="0 0 -0.01"/>
      <geometry>
        <mesh filename="package://turtlebot_description/meshes/sensors/sensor_pole.dae"/>
      </geometry>
    </visual>
    <collision>
      <origin rpy="0 0 0" xyz="0 0 0"/>
      <geometry>
        <cylinder length="0.0936" radius="0.006"/>
      </geometry>
    </collision>
    <inertial>
      <mass value="0.020"/>
      <origin xyz="0 0 0"/>
      <inertia ixx="0.000014782" ixy="0.0" ixz="0.0" iyy="0.000014782" iyz="0.0" izz="0.000000360"/>
    </inertial>
  </link>
  <joint name="pole_kinect_1_joint" type="fixed">
    <origin rpy="0 0 0" xyz="-0.1024 -0.098 0.2372"/>
    <parent link="base_link"/>
    <child link="pole_kinect_1_link"/>
  </joint>
  <link name="pole_kinect_1_link">
    <visual>
      <origin rpy="0 0 0" xyz="0 0 -0.01"/>
      <geometry>
        <mesh filename="package://turtlebot_description/meshes/sensors/sensor_pole.dae"/>
      </geometry>
    </visual>
    <collision>
      <origin rpy="0 0 0" xyz="0 0 0"/>
      <geometry>
        <cylinder length="0.0936" radius="0.006"/>
      </geometry>
    </collision>
    <inertial>
      <mass value="0.020"/>
      <origin xyz="0 0 0"/>
      <inertia ixx="0.000014782" ixy="0.0" ixz="0.0" iyy="0.000014782" iyz="0.0" izz="0.000000360"/>
    </inertial>
  </link>
  <joint name="plate_top_joint" type="fixed">
    <origin rpy="0 0 0" xyz="-0.01364 0.0  0.3966"/>
    <parent link="base_link"/>
    <child link="plate_top_link"/>
  </joint>
  <link name="plate_top_link">
    <visual>
      <origin rpy="0 0 0" xyz="0 0 0"/>
      <geometry>
        <mesh filename="package://turtlebot_description/meshes/stacks/hexagons/plate_top.dae"/>
      </geometry>
    </visual>
    <collision>
      <origin rpy="0 0 0" xyz="0.01364 0 0"/>
      <geometry>
        <cylinder length="0.006" radius="0.170"/>
      </geometry>
    </collision>
    <inertial>
      <mass value="0.520"/>
      <origin xyz="0 0 0"/>
      <inertia ixx="0.003328" ixy="0.0" ixz="0.0" iyy="0.003328" iyz="0.0" izz="0.006656"/>
    </inertial>
  </link>
  <joint name="camera_rgb_joint" type="fixed">
    <origin rpy="0 -0.035 0" xyz="-0.087 -0.0125 0.287"/>
    <parent link="base_link"/>
    <child link="camera_rgb_frame"/>
  </joint>
  <link name="camera_rgb_frame"/>
  <joint name="camera_rgb_optical_joint" type="fixed">
    <origin rpy="-1.5706 0 -1.5706" xyz="0 0 0"/>
    <parent link="camera_rgb_frame"/>
    <child link="camera_rgb_optical_frame"/>
  </joint>
  <link name="camera_rgb_optical_frame"/>
  <joint name="camera_joint" type="fixed">
    <origin rpy="0 0 0" xyz="-0.031 0.0125 -0.016"/>
    <parent link="camera_rgb_frame"/>
    <child link="camera_link"/>
  </joint>
  <link name="camera_link">
    <visual>
      <origin rpy="0 0 1.5706" xyz="0 0 0"/>
      <geometry>
        <mesh filename="package://turtlebot_description/meshes/sensors/kinect.dae"/>
      </geometry>
    </visual>
    <collision>
      <origin rpy="0 0 0" xyz="0.0 0.0 0.0"/>
      <geometry>
        <box size="0.07271 0.27794 0.073"/>
      </geometry>
    </collision>
    <inertial>
      <mass value="0.564"/>
      <origin xyz="0 0 0"/>
      <inertia ixx="0.003881243" ixy="0.0" ixz="0.0" iyy="0.000498940" iyz="0.0" izz="0.003879257"/>
    </inertial>
  </link>
  <!-- The fixed joints & links below are usually published by static_transformers launched by the OpenNi launch 
         files. However, for Gazebo simulation we need them, so we add them here.
         (Hence, don't publish them additionally!) -->
  <joint name="camera_depth_joint" type="fixed">
    <origin rpy="0 0 0" xyz="0 0.025 0"/>
    <parent link="camera_rgb_frame"/>
    <child link="camera_depth_frame"/>
  </joint>
  <link name="camera_depth_frame"/>
  <joint name="camera_depth_optical_joint" type="fixed">
    <origin rpy="-1.5706 0 -1.5706" xyz="0 0 0"/>
    <parent link="camera_depth_frame"/>
    <child link="camera_depth_optical_frame"/>
  </joint>
  <link name="camera_depth_optical_frame"/>
  <!-- Kinect sensor for simulation -->
  <gazebo reference="camera_link">
    <sensor name="camera" type="depth">
      <always_on>true</always_on>
      <update_rate>20.0</update_rate>
      <camera>
        <horizontal_fov>1.04706666667</horizontal_fov>
        <image>
          <format>R8G8B8</format>
          <width>640</width>
          <height>480</height>
        </image>
        <clip>
          <near>0.05</near>
          <far>8.0</far>
        </clip>
      </camera>
      <plugin filename="libgazebo_ros_openni_kinect.so" name="kinect_camera_controller">
        <cameraName>camera</cameraName>
        <alwaysOn>true</alwaysOn>
        <updateRate>10</updateRate>
        <imageTopicName>rgb/image_raw</imageTopicName>
        <depthImageTopicName>depth/image_raw</depthImageTopicName>
        <pointCloudTopicName>depth/points</pointCloudTopicName>
        <cameraInfoTopicName>rgb/camera_info</cameraInfoTopicName>
        <depthImageCameraInfoTopicName>depth/camera_info</depthImageCameraInfoTopicName>
        <frameName>camera_depth_optical_frame</frameName>
        <baseline>0.1</baseline>
        <distortion_k1>0.0</distortion_k1>
        <distortion_k2>0.0</distortion_k2>
        <distortion_k3>0.0</distortion_k3>
        <distortion_t1>0.0</distortion_t1>
        <distortion_t2>0.0</distortion_t2>
        <pointCloudCutoff>0.4</pointCloudCutoff>
      </plugin>
    </sensor>
  </gazebo>
  <!--' every urdf should have a base link '-->
  <link name="elevator_stem_link">
    <inertial>
      <origin rpy="0 0 0" xyz="0 0 0.5"/>
      <mass value="1"/>
      <inertia ixx="10" ixy="0" ixz="0" iyy="10" iyz="0" izz="10"/>
    </inertial>
    <visual>
      <origin rpy="0 0 0" xyz="0 0 0"/>
      <geometry>
        <box size="0.025 0.025 0.84455"/>
      </geometry>
      <material name="Grey">
        <color rgba="0 1.0 1.0 1.0"/>
      </material>
    </visual>
    <collision>
      <origin rpy="0 0 0" xyz="0 0 0"/>
      <geometry>
        <box size="0.025 0.025 0.84455"/>
      </geometry>
    </collision>
  </link>
  <link name="elevator_slider_link">
    <visual>
      <origin rpy="0 0 0" xyz="0 0 0"/>
      <geometry>
        <box size="0.025 0.025 0.1"/>
      </geometry>
      <material name="White">
        <color rgba="0 0 0 1.0"/>
      </material>
    </visual>
  </link>
  <link name="elevator_arm_adapter_link">
    <inertial>
      <origin rpy="0 0 0" xyz="0 0 0.5"/>
      <mass value="1"/>
      <inertia ixx="100" ixy="0" ixz="0" iyy="100" iyz="0" izz="100"/>
    </inertial>
    <visual>
      <origin rpy="0 0 0" xyz="0 0 0"/>
      <geometry>
        <box size="0.025 0.075 0.1"/>
      </geometry>
      <material name="White">
        <color rgba="0 1.0 1.0 1.0"/>
      </material>
    </visual>
    <collision>
      <origin rpy="0 0 0" xyz="0 0 0"/>
      <geometry>
        <box size="0.025 0.075 0.1"/>
      </geometry>
    </collision>
  </link>
  <!-- Change below to alter where the elevator will attach to on the turtlebot. xacro should replace the base_link and constants for location -->
  <joint name="elevator_base" type="fixed">
    <!-- <origin xyz="0.025 0 0.825"/> -->
    <!-- <parent link="base_link"/> -->
    <origin rpy="0 0 0" xyz="0.0508 0 0.422275"/>
    <parent link="plate_top_link"/>
    <child link="elevator_stem_link"/>
  </joint>
  <joint name="Slider" type="fixed">
    <parent link="elevator_stem_link"/>
    <child link="elevator_slider_link"/>
    <origin rpy="0 0 0" xyz="0 0 0"/>
    <axis xyz="0 0 1"/>
    <limit effort="30" lower="-0.25" upper="0.25" velocity="0.25"/>
  </joint>
  <joint name="arm_adapter" type="fixed">
    <parent link="elevator_slider_link"/>
    <child link="elevator_arm_adapter_link"/>
    <origin rpy="0 0 0" xyz="0.025 0 0"/>
  </joint>
  <!--Attach the turtlebot arm to the elevator which connects(at this moment) to the top hexagon plate -->
  <link name="arm_base_link"/>
  <joint name="arm_base_joint" type="fixed">
    <origin rpy="3.142 -1.571 0" xyz="0.0889 0 0"/>
    <parent link="elevator_arm_adapter_link"/>
    <child link="arm_base_link"/>
  </joint>
  <!-- fake gripper_link joint gives us a free servo!
         this makes us 5DOF and saves you $44.90
         that's a lot of coin! -->
  <link name="gripper_link"/>
  <joint name="gripper_link_joint" type="revolute">
    <origin rpy="0 -1.57 0" xyz="0 0 .112"/>
    <parent link="arm_wrist_flex_link"/>
    <child link="gripper_link"/>
    <limit effort="30" lower="-3.14" upper="3.14" velocity="1"/>
    <axis xyz="1 0 0"/>
  </joint>
  <!-- shoulder pan joint -->
  <joint name="arm_shoulder_pan_servo_joint" type="fixed">
    <origin rpy="1.5706 0 1.5706" xyz="0 0 0"/>
    <parent link="arm_base_link"/>
    <child link="arm_shoulder_pan_servo_link"/>
  </joint>
  <link name="arm_shoulder_pan_servo_link">
    <inertial>
      <mass value="0.00001"/>
      <origin xyz="0 0 0"/>
      <inertia ixx="1.0" ixy="0.0" ixz="0.0" iyy="1.0" iyz="0.0" izz="1.0"/>
    </inertial>
    <visual>
      <origin rpy="0 0 0" xyz=" 0 0 0 "/>
      <geometry>
        <mesh filename="package://turtlebot_arm_description/meshes/ax12_box.stl" scale="0.001 0.001 0.001"/>
      </geometry>
      <material name="black"/>
    </visual>
    <collision>
      <origin rpy="0 0 0" xyz="0.0 0.0 -0.01241"/>
      <geometry>
        <box size="0.025 0.038 0.04762"/>
      </geometry>
    </collision>
  </link>
  <joint name="arm_shoulder_pan_joint" type="revolute">
    <origin rpy="-1.5706 1.5706 3.1412" xyz="0 0.019 0"/>
    <axis xyz="0 0 -1"/>
    <limit effort="30" lower="-2.617" upper="2.617" velocity="1.571"/>
    <parent link="arm_shoulder_pan_servo_link"/>
    <child link="arm_shoulder_pan_link"/>
  </joint>
  <link name="arm_shoulder_pan_link">
    <inertial>
      <mass value="0.00001"/>
      <origin xyz="0 0 0"/>
      <inertia ixx="1.0" ixy="0.0" ixz="0.0" iyy="1.0" iyz="0.0" izz="1.0"/>
    </inertial>
    <visual>
      <origin rpy="0 0 0" xyz=" 0 0 0 "/>
      <geometry>
        <mesh filename="package://turtlebot_arm_description/meshes/F3.stl" scale="0.001 0.001 0.001"/>
      </geometry>
      <material name="white"/>
    </visual>
    <collision>
      <origin rpy="0 0 0" xyz="0.0 0.0 -0.0045"/>
      <geometry>
        <box size="0.025 0.038 0.009"/>
      </geometry>
    </collision>
  </link>
  <!-- shoulder lift joint -->
  <joint name="arm_shoulder_lift_servo_joint" type="fixed">
    <origin rpy="0 3.1412 0" xyz="0 0 -0.0415"/>
    <parent link="arm_shoulder_pan_link"/>
    <child link="arm_shoulder_lift_servo_link"/>
  </joint>
  <link name="arm_shoulder_lift_servo_link">
    <inertial>
      <mass value="0.00001"/>
      <origin xyz="0 0 0"/>
      <inertia ixx="1.0" ixy="0.0" ixz="0.0" iyy="1.0" iyz="0.0" izz="1.0"/>
    </inertial>
    <visual>
      <origin rpy="0 0 0" xyz=" 0 0 0 "/>
      <geometry>
        <mesh filename="package://turtlebot_arm_description/meshes/ax12_box.stl" scale="0.001 0.001 0.001"/>
      </geometry>
      <material name="black"/>
    </visual>
    <collision>
      <origin rpy="0 0 0" xyz="0.0 0.0 -0.01241"/>
      <geometry>
        <box size="0.025 0.038 0.04762"/>
      </geometry>
    </collision>
  </link>
  <joint name="arm_shoulder_lift_joint" type="revolute">
    <origin rpy="0 0 0" xyz="0 0 0"/>
    <axis xyz="0 1 0"/>
    <limit effort="30" lower="-2.617" upper="2.617" velocity="1.571"/>
    <parent link="arm_shoulder_lift_servo_link"/>
    <child link="arm_shoulder_lift_link"/>
  </joint>
  <link name="arm_shoulder_lift_link">
    <inertial>
      <mass value="0.00001"/>
      <origin xyz="0 0 0"/>
      <inertia ixx="1.0" ixy="0.0" ixz="0.0" iyy="1.0" iyz="0.0" izz="1.0"/>
    </inertial>
    <visual>
      <origin rpy="0 0 0" xyz=" 0 0 0 "/>
      <geometry>
        <mesh filename="package://turtlebot_arm_description/meshes/F4.stl" scale="0.001 0.001 0.001"/>
      </geometry>
      <material name="white"/>
    </visual>
    <collision>
      <origin rpy="0 0 0" xyz="0.0 0.0 0.0215"/>
      <geometry>
        <box size="0.028 0.0485 0.065"/>
      </geometry>
    </collision>
  </link>
  <joint name="arm_shoulder_F10_0_joint" type="fixed">
    <origin rpy="0 0 0" xyz="0 0 0.0545"/>
    <parent link="arm_shoulder_lift_link"/>
    <child link="arm_shoulder_F10_0_link"/>
  </joint>
  <link name="arm_shoulder_F10_0_link">
    <inertial>
      <mass value="0.00001"/>
      <origin xyz="0 0 0"/>
      <inertia ixx="1.0" ixy="0.0" ixz="0.0" iyy="1.0" iyz="0.0" izz="1.0"/>
    </inertial>
    <visual>
      <origin rpy="0 0 0" xyz=" 0 0 0 "/>
      <geometry>
        <mesh filename="package://turtlebot_arm_description/meshes/F10.stl" scale="0.001 0.001 0.001"/>
      </geometry>
      <material name="white"/>
    </visual>
    <collision>
      <origin rpy="0 0 0" xyz="0.0 0.0 0.0"/>
      <geometry>
        <box size="0.025 0.038 0.004"/>
      </geometry>
    </collision>
  </link>
  <joint name="arm_shoulder_F10_1_joint" type="fixed">
    <origin rpy="0 0 0" xyz="0 0 0.004"/>
    <parent link="arm_shoulder_F10_0_link"/>
    <child link="arm_shoulder_F10_1_link"/>
  </joint>
  <link name="arm_shoulder_F10_1_link">
    <inertial>
      <mass value="0.00001"/>
      <origin xyz="0 0 0"/>
      <inertia ixx="1.0" ixy="0.0" ixz="0.0" iyy="1.0" iyz="0.0" izz="1.0"/>
    </inertial>
    <visual>
      <origin rpy="0 0 0" xyz=" 0 0 0 "/>
      <geometry>
        <mesh filename="package://turtlebot_arm_description/meshes/F10.stl" scale="0.001 0.001 0.001"/>
      </geometry>
      <material name="white"/>
    </visual>
    <collision>
      <origin rpy="0 0 0" xyz="0.0 0.0 0.0"/>
      <geometry>
        <box size="0.025 0.038 0.004"/>
      </geometry>
    </collision>
  </link>
  <joint name="arm_shoulder_F10_2_joint" type="fixed">
    <origin rpy="0 0 0" xyz="0 0 0.004"/>
    <parent link="arm_shoulder_F10_1_link"/>
    <child link="arm_shoulder_F10_2_link"/>
  </joint>
  <link name="arm_shoulder_F10_2_link">
    <inertial>
      <mass value="0.00001"/>
      <origin xyz="0 0 0"/>
      <inertia ixx="1.0" ixy="0.0" ixz="0.0" iyy="1.0" iyz="0.0" izz="1.0"/>
    </inertial>
    <visual>
      <origin rpy="0 0 0" xyz=" 0 0 0 "/>
      <geometry>
        <mesh filename="package://turtlebot_arm_description/meshes/F10.stl" scale="0.001 0.001 0.001"/>
      </geometry>
      <material name="white"/>
    </visual>
    <collision>
      <origin rpy="0 0 0" xyz="0.0 0.0 0.0"/>
      <geometry>
        <box size="0.025 0.038 0.004"/>
      </geometry>
    </collision>
  </link>
  <joint name="arm_shoulder_F3_0_joint" type="fixed">
    <origin rpy="0 3.1412 0" xyz="0 0 0.002"/>
    <parent link="arm_shoulder_F10_2_link"/>
    <child link="arm_shoulder_F3_0_link"/>
  </joint>
  <link name="arm_shoulder_F3_0_link">
    <inertial>
      <mass value="0.00001"/>
      <origin xyz="0 0 0"/>
      <inertia ixx="1.0" ixy="0.0" ixz="0.0" iyy="1.0" iyz="0.0" izz="1.0"/>
    </inertial>
    <visual>
      <origin rpy="0 0 0" xyz=" 0 0 0 "/>
      <geometry>
        <mesh filename="package://turtlebot_arm_description/meshes/F3.stl" scale="0.001 0.001 0.001"/>
      </geometry>
      <material name="white"/>
    </visual>
    <collision>
      <origin rpy="0 0 0" xyz="0.0 0.0 -0.0045"/>
      <geometry>
        <box size="0.025 0.038 0.009"/>
      </geometry>
    </collision>
  </link>
  <!-- elbow joint -->
  <joint name="arm_elbow_flex_servo_joint" type="fixed">
    <origin rpy="0 3.1412 0" xyz="0 0 -0.0415"/>
    <parent link="arm_shoulder_F3_0_link"/>
    <child link="arm_elbow_flex_servo_link"/>
  </joint>
  <link name="arm_elbow_flex_servo_link">
    <inertial>
      <mass value="0.00001"/>
      <origin xyz="0 0 0"/>
      <inertia ixx="1.0" ixy="0.0" ixz="0.0" iyy="1.0" iyz="0.0" izz="1.0"/>
    </inertial>
    <visual>
      <origin rpy="0 0 0" xyz=" 0 0 0 "/>
      <geometry>
        <mesh filename="package://turtlebot_arm_description/meshes/ax12_box.stl" scale="0.001 0.001 0.001"/>
      </geometry>
      <material name="black"/>
    </visual>
    <collision>
      <origin rpy="0 0 0" xyz="0.0 0.0 -0.01241"/>
      <geometry>
        <box size="0.025 0.038 0.04762"/>
      </geometry>
    </collision>
  </link>
  <joint name="arm_elbow_flex_joint" type="revolute">
    <origin rpy="0 0 0" xyz="0 0 0"/>
    <axis xyz="0 1 0"/>
    <limit effort="30" lower="-2.617" upper="2.617" velocity="1.571"/>
    <parent link="arm_elbow_flex_servo_link"/>
    <child link="arm_elbow_flex_link"/>
  </joint>
  <link name="arm_elbow_flex_link">
    <inertial>
      <mass value="0.00001"/>
      <origin xyz="0 0 0"/>
      <inertia ixx="1.0" ixy="0.0" ixz="0.0" iyy="1.0" iyz="0.0" izz="1.0"/>
    </inertial>
    <visual>
      <origin rpy="0 0 0" xyz=" 0 0 0 "/>
      <geometry>
        <mesh filename="package://turtlebot_arm_description/meshes/F4.stl" scale="0.001 0.001 0.001"/>
      </geometry>
      <material name="white"/>
    </visual>
    <collision>
      <origin rpy="0 0 0" xyz="0.0 0.0 0.0215"/>
      <geometry>
        <box size="0.028 0.0485 0.065"/>
      </geometry>
    </collision>
  </link>
  <joint name="arm_elbow_F10_0_joint" type="fixed">
    <origin rpy="0 0 0" xyz="0 0 0.0545"/>
    <parent link="arm_elbow_flex_link"/>
    <child link="arm_elbow_F10_0_link"/>
  </joint>
  <link name="arm_elbow_F10_0_link">
    <inertial>
      <mass value="0.00001"/>
      <origin xyz="0 0 0"/>
      <inertia ixx="1.0" ixy="0.0" ixz="0.0" iyy="1.0" iyz="0.0" izz="1.0"/>
    </inertial>
    <visual>
      <origin rpy="0 0 0" xyz=" 0 0 0 "/>
      <geometry>
        <mesh filename="package://turtlebot_arm_description/meshes/F10.stl" scale="0.001 0.001 0.001"/>
      </geometry>
      <material name="white"/>
    </visual>
    <collision>
      <origin rpy="0 0 0" xyz="0.0 0.0 0.0"/>
      <geometry>
        <box size="0.025 0.038 0.004"/>
      </geometry>
    </collision>
  </link>
  <joint name="arm_elbow_F10_1_joint" type="fixed">
    <origin rpy="0 0 0" xyz="0 0 0.004"/>
    <parent link="arm_elbow_F10_0_link"/>
    <child link="arm_elbow_F10_1_link"/>
  </joint>
  <link name="arm_elbow_F10_1_link">
    <inertial>
      <mass value="0.00001"/>
      <origin xyz="0 0 0"/>
      <inertia ixx="1.0" ixy="0.0" ixz="0.0" iyy="1.0" iyz="0.0" izz="1.0"/>
    </inertial>
    <visual>
      <origin rpy="0 0 0" xyz=" 0 0 0 "/>
      <geometry>
        <mesh filename="package://turtlebot_arm_description/meshes/F10.stl" scale="0.001 0.001 0.001"/>
      </geometry>
      <material name="white"/>
    </visual>
    <collision>
      <origin rpy="0 0 0" xyz="0.0 0.0 0.0"/>
      <geometry>
        <box size="0.025 0.038 0.004"/>
      </geometry>
    </collision>
  </link>
  <joint name="arm_elbow_F10_2_joint" type="fixed">
    <origin rpy="0 0 0" xyz="0 0 0.004"/>
    <parent link="arm_elbow_F10_1_link"/>
    <child link="arm_elbow_F10_2_link"/>
  </joint>
  <link name="arm_elbow_F10_2_link">
    <inertial>
      <mass value="0.00001"/>
      <origin xyz="0 0 0"/>
      <inertia ixx="1.0" ixy="0.0" ixz="0.0" iyy="1.0" iyz="0.0" izz="1.0"/>
    </inertial>
    <visual>
      <origin rpy="0 0 0" xyz=" 0 0 0 "/>
      <geometry>
        <mesh filename="package://turtlebot_arm_description/meshes/F10.stl" scale="0.001 0.001 0.001"/>
      </geometry>
      <material name="white"/>
    </visual>
    <collision>
      <origin rpy="0 0 0" xyz="0.0 0.0 0.0"/>
      <geometry>
        <box size="0.025 0.038 0.004"/>
      </geometry>
    </collision>
  </link>
  <joint name="arm_elbow_F3_0_joint" type="fixed">
    <origin rpy="0 3.1412 0" xyz="0 0 0.002"/>
    <parent link="arm_elbow_F10_2_link"/>
    <child link="arm_elbow_F3_0_link"/>
  </joint>
  <link name="arm_elbow_F3_0_link">
    <inertial>
      <mass value="0.00001"/>
      <origin xyz="0 0 0"/>
      <inertia ixx="1.0" ixy="0.0" ixz="0.0" iyy="1.0" iyz="0.0" izz="1.0"/>
    </inertial>
    <visual>
      <origin rpy="0 0 0" xyz=" 0 0 0 "/>
      <geometry>
        <mesh filename="package://turtlebot_arm_description/meshes/F3.stl" scale="0.001 0.001 0.001"/>
      </geometry>
      <material name="white"/>
    </visual>
    <collision>
      <origin rpy="0 0 0" xyz="0.0 0.0 -0.0045"/>
      <geometry>
        <box size="0.025 0.038 0.009"/>
      </geometry>
    </collision>
  </link>
  <!-- wrist joint -->
  <joint name="arm_wrist_flex_servo_joint" type="fixed">
    <origin rpy="0 3.1412 0" xyz="0 0 -0.0415"/>
    <parent link="arm_elbow_F3_0_link"/>
    <child link="arm_wrist_flex_servo_link"/>
  </joint>
  <link name="arm_wrist_flex_servo_link">
    <inertial>
      <mass value="0.00001"/>
      <origin xyz="0 0 0"/>
      <inertia ixx="1.0" ixy="0.0" ixz="0.0" iyy="1.0" iyz="0.0" izz="1.0"/>
    </inertial>
    <visual>
      <origin rpy="0 0 0" xyz=" 0 0 0 "/>
      <geometry>
        <mesh filename="package://turtlebot_arm_description/meshes/ax12_box.stl" scale="0.001 0.001 0.001"/>
      </geometry>
      <material name="black"/>
    </visual>
    <collision>
      <origin rpy="0 0 0" xyz="0.0 0.0 -0.01241"/>
      <geometry>
        <box size="0.025 0.038 0.04762"/>
      </geometry>
    </collision>
  </link>
  <joint name="arm_wrist_flex_joint" type="revolute">
    <origin rpy="0 0 0" xyz="0 0 0"/>
    <axis xyz="0 1 0"/>
    <limit effort="30" lower="-1.745" upper="1.745" velocity="1.571"/>
    <parent link="arm_wrist_flex_servo_link"/>
    <child link="arm_wrist_flex_link"/>
  </joint>
  <link name="arm_wrist_flex_link">
    <inertial>
      <mass value="0.00001"/>
      <origin xyz="0 0 0"/>
      <inertia ixx="1.0" ixy="0.0" ixz="0.0" iyy="1.0" iyz="0.0" izz="1.0"/>
    </inertial>
    <visual>
      <origin rpy="0 0 0" xyz=" 0 0 0 "/>
      <geometry>
        <mesh filename="package://turtlebot_arm_description/meshes/F2.stl" scale="0.001 0.001 0.001"/>
      </geometry>
      <material name="white"/>
    </visual>
    <collision>
      <origin rpy="0 0 0" xyz="0.0 0.0 0.00775"/>
      <geometry>
        <box size="0.025 0.0485 0.0375"/>
      </geometry>
    </collision>
  </link>
  <joint name="arm_wrist_F3_0_joint" type="fixed">
    <origin rpy="0 3.1412 -1.5706" xyz="0 0.016 0.0265"/>
    <parent link="arm_wrist_flex_link"/>
    <child link="arm_wrist_F3_0_link"/>
  </joint>
  <link name="arm_wrist_F3_0_link">
    <inertial>
      <mass value="0.00001"/>
      <origin xyz="0 0 0"/>
      <inertia ixx="1.0" ixy="0.0" ixz="0.0" iyy="1.0" iyz="0.0" izz="1.0"/>
    </inertial>
    <visual>
      <origin rpy="0 0 0" xyz=" 0 0 0 "/>
      <geometry>
        <mesh filename="package://turtlebot_arm_description/meshes/F3.stl" scale="0.001 0.001 0.001"/>
      </geometry>
      <material name="white"/>
    </visual>
    <collision>
      <origin rpy="0 0 0" xyz="0.0 0.0 -0.0045"/>
      <geometry>
        <box size="0.025 0.038 0.009"/>
      </geometry>
    </collision>
  </link>
  <!-- gripper joint -->
  <joint name="gripper_servo_joint" type="fixed">
    <origin rpy="3.1412 1.5706 0" xyz="-0.02275 0 -0.019"/>
    <parent link="arm_wrist_F3_0_link"/>
    <child link="gripper_servo_link"/>
  </joint>
  <link name="gripper_servo_link">
    <inertial>
      <mass value="0.00001"/>
      <origin xyz="0 0 0"/>
      <inertia ixx="1.0" ixy="0.0" ixz="0.0" iyy="1.0" iyz="0.0" izz="1.0"/>
    </inertial>
    <visual>
      <origin rpy="0 0 0" xyz=" 0 0 0 "/>
      <geometry>
        <mesh filename="package://turtlebot_arm_description/meshes/ax12_box.stl" scale="0.001 0.001 0.001"/>
      </geometry>
      <material name="black"/>
    </visual>
    <collision>
      <origin rpy="0 0 0" xyz="0.0 0.0 -0.01241"/>
      <geometry>
        <box size="0.025 0.038 0.04762"/>
      </geometry>
    </collision>
  </link>
  <!-- finger 1 -->
  <joint name="gripper_joint" type="revolute">
    <origin rpy="0 0 0" xyz="0 0 0"/>
    <axis xyz="0 1 0"/>
    <limit effort="30" lower="-0.40" upper="0.46" velocity="0.785"/>
    <parent link="gripper_servo_link"/>
    <child link="gripper_active_link"/>
  </joint>
  <link name="gripper_active_link">
    <inertial>
      <mass value="0.00001"/>
      <origin xyz="0 0 0"/>
      <inertia ixx="1.0" ixy="0.0" ixz="0.0" iyy="1.0" iyz="0.0" izz="1.0"/>
    </inertial>
    <visual>
      <origin rpy="0 0 0" xyz=" 0 0 0 "/>
      <geometry>
        <mesh filename="package://turtlebot_arm_description/meshes/F2.stl" scale="0.001 0.001 0.001"/>
      </geometry>
      <material name="white"/>
    </visual>
    <collision>
      <origin rpy="0 0 0" xyz="0.0 0.0 0.00775"/>
      <geometry>
        <box size="0.025 0.0485 0.0375"/>
      </geometry>
    </collision>
  </link>
  <joint name="gripper_active_finger_joint" type="fixed">
    <origin rpy="0 0 0" xyz="0 0 0.0265"/>
    <parent link="gripper_active_link"/>
    <child link="gripper_active_finger_link"/>
  </joint>
  <link name="gripper_active_finger_link">
    <inertial>
      <mass value="0.00001"/>
      <origin xyz="0 0 0"/>
      <inertia ixx="1.0" ixy="0.0" ixz="0.0" iyy="1.0" iyz="0.0" izz="1.0"/>
    </inertial>
    <visual>
      <origin rpy="0 0 0" xyz=" 0 0 0 "/>
      <geometry>
        <mesh filename="package://turtlebot_arm_description/meshes/finger.stl" scale="0.001 0.001 0.001"/>
      </geometry>
      <material name="green"/>
    </visual>
    <collision>
      <origin rpy="0 0 0" xyz="0.02645 0.0 -0.00655"/>
      <geometry>
        <box size="0.0783 0.03801 0.0193"/>
      </geometry>
    </collision>
  </link>
  <!-- finger 2 -->
  <joint name="gripper_static_joint" type="fixed">
    <origin rpy="0 3.1412 0" xyz="0 0 -0.0415"/>
    <parent link="gripper_servo_link"/>
    <child link="gripper_static_link"/>
  </joint>
  <link name="gripper_static_link">
    <inertial>
      <mass value="0.00001"/>
      <origin xyz="0 0 0"/>
      <inertia ixx="1.0" ixy="0.0" ixz="0.0" iyy="1.0" iyz="0.0" izz="1.0"/>
    </inertial>
    <visual>
      <origin rpy="0 0 0" xyz=" 0 0 0 "/>
      <geometry>
        <mesh filename="package://turtlebot_arm_description/meshes/F3.stl" scale="0.001 0.001 0.001"/>
      </geometry>
      <material name="white"/>
    </visual>
    <collision>
      <origin rpy="0 0 0" xyz="0.0 0.0 -0.0045"/>
      <geometry>
        <box size="0.025 0.038 0.009"/>
      </geometry>
    </collision>
  </link>
  <joint name="gripper_static_finger_joint" type="fixed">
    <origin rpy="0 0 3.1412" xyz="0 0 0"/>
    <parent link="gripper_static_link"/>
    <child link="gripper_static_finger_link"/>
  </joint>
  <link name="gripper_static_finger_link">
    <inertial>
      <mass value="0.00001"/>
      <origin xyz="0 0 0"/>
      <inertia ixx="1.0" ixy="0.0" ixz="0.0" iyy="1.0" iyz="0.0" izz="1.0"/>
    </inertial>
    <visual>
      <origin rpy="0 0 0" xyz=" 0 0 0 "/>
      <geometry>
        <mesh filename="package://turtlebot_arm_description/meshes/finger.stl" scale="0.001 0.001 0.001"/>
      </geometry>
      <material name="green"/>
    </visual>
    <collision>
      <origin rpy="0 0 0" xyz="0.02645 0.0 -0.00655"/>
      <geometry>
        <box size="0.0783 0.03801 0.0193"/>
      </geometry>
    </collision>
  </link>
  <!--Webcameras. Parameters need to be tuned -->
  <link name="arm_cam_frame">
    <visual>
      <geometry>
        <box size="0.0254 0.05 0.0125"/>
      </geometry>
      <material name="blue">
        <color rgba="0 0 .8 1"/>
      </material>
    </visual>
    <collision>
      <geometry>
        <box size="0.0254 0.05 0.0125"/>
      </geometry>
    </collision>
    <inertial>
      <mass value="0.01"/>
      <origin xyz="0 0 0"/>
      <inertia ixx="0.001" ixy="0.0" ixz="0.0" iyy="0.001" iyz="0.0" izz="0.001"/>
    </inertial>
  </link>
  <!-- attached pysical link to a parent -->
  <joint name="arm_cam_frame_joint" type="fixed">
    <origin xyz="0.0254 -0.07 -0.0254"/>
    <parent link="arm_wrist_F3_0_link"/>
    <child link="arm_cam_frame"/>
  </joint>
  <!-- Define where the optical frame is in relation to the physical camera center -->
  <joint name="arm_cam_optical_frame_joint" type="fixed">
    <origin rpy="-1.5706 0.0 -1.5706" xyz="0 0 0"/>
    <parent link="arm_cam_frame"/>
    <child link="arm_cam_optical_frame"/>
  </joint>
  <link name="arm_cam_optical_frame"/>
  <!-- extensions -->
  <!-- rpy="1.5708 -0.345 0" rotated on its side and tilted up about 20 degrees -->
  <!-- rpy="1.5708 -1.222 0" rotated on its side and tilted up about 70 degrees so the optical Z axis is pointing out of the lens -->
  <link name="head_cam_frame">
    <visual>
      <geometry>
        <box size="0.0254 0.05 0.0125"/>
      </geometry>
      <material name="blue">
        <color rgba="0 0 .8 1"/>
      </material>
    </visual>
    <collision>
      <geometry>
        <box size="0.0254 0.05 0.0125"/>
      </geometry>
    </collision>
    <inertial>
      <mass value="0.01"/>
      <origin xyz="0 0 0"/>
      <inertia ixx="0.001" ixy="0.0" ixz="0.0" iyy="0.001" iyz="0.0" izz="0.001"/>
    </inertial>
  </link>
  <!-- attached pysical link to a parent -->
  <joint name="head_cam_frame_joint" type="fixed">
    <origin rpy="-1.571 -1.222 0 " xyz="-0.06985 0 0.663575"/>
    <parent link="elevator_stem_link"/>
    <child link="head_cam_frame"/>
  </joint>
  <!-- Define where the optical frame is in relation to the physical camera center -->
  <joint name="head_cam_optical_frame_joint" type="fixed">
    <origin rpy="-1.5706 0.0 -1.5706" xyz="0 0 0"/>
    <parent link="head_cam_frame"/>
    <child link="head_cam_optical_frame"/>
  </joint>
  <link name="head_cam_optical_frame"/>
  <!-- extensions -->
</robot>
